Workbook
Name A_Benefits: Assumptions!$C$27
Name A_Bonus: Assumptions!$C$26
Name A_Capex: Assumptions!$C$32
Name A_Cash0: Assumptions!$C$35
Name A_CSCogs: Assumptions!$C$17
Name A_DeptHires: Assumptions!$E$40:$G$45
Name A_DeptNames: Assumptions!$A$40:$A$45
Name A_DeptSal: Assumptions!$D$40:$D$45
Name A_DeptStart: Assumptions!$C$40:$C$45
Name A_DR0: Assumptions!$C$36
Name A_EntARPU0: Assumptions!$C$12
Name A_EntCust0: Assumptions!$C$10
Name A_HireYears: Assumptions!$E$39:$G$39
Name A_HostPct: Assumptions!$C$16
Name A_Life: Assumptions!$C$33
Name A_Load: Assumptions!$C$29
Name A_MktgG: Assumptions!$C$23
Name A_MMARPU0: Assumptions!$C$13
Name A_MMCust0: Assumptions!$C$11
Name A_ProfFees: Assumptions!$C$21
Name A_ProfG: Assumptions!$C$22
Name A_PTax: Assumptions!$C$28
Name A_RentHead: Assumptions!$C$19
Name A_SoftHead: Assumptions!$C$18
Name A_TaxRate: Assumptions!$C$34
Name A_TravelPct: Assumptions!$C$20
Name L_ChurnEnt: 'Scenario Manager'!$F$12
Name L_ChurnMM: 'Scenario Manager'!$F$13
Name L_ExpEnt: 'Scenario Manager'!$F$14
Name L_ExpMM: 'Scenario Manager'!$F$15
Name L_HirePace: 'Scenario Manager'!$F$17
Name L_Mktg: 'Scenario Manager'!$F$18
Name L_NewEnt: 'Scenario Manager'!$F$10
Name L_NewMM: 'Scenario Manager'!$F$11
Name L_Price: 'Scenario Manager'!$F$16
Name L_SalInfl: 'Scenario Manager'!$F$19
Name ModelStart: Assumptions!$C$6
Name ScenarioList: 'Scenario Manager'!$C$9:$E$9
Name ScenarioSel: 'Scenario Manager'!$C$6

Sheet Cover
B4: NOVAFLOW ANALYTICS
B5: Three-Year Operating Plan and SaaS KPI Model
B6: FY2026 to FY2028 | Monthly engine | Scenario-driven
B10: THE BUSINESS IN BRIEF
B12: B2B SaaS: workflow analytics for enterprise and mid-market operations teams.
B13: Two tiers: Professional (mid-market, monthly billing) and Enterprise (annual upfront).
B14: Growth: steady new-logo adds, ~4%/yr pricing, expansion-led NRR above 100% in Enterprise.
B15: Plan: ARR ~$4m to ~$15m, EBITDA margin ~-65% to ~-16%, funded by an $18m Series B.
B16: Full narrative and reading guide on the Instructions sheet.
B19: CONTENTS
B21: Instructions | D21: How the model works, colour legend, checks panel, V2 roadmap
B22: Assumptions | D22: All static inputs: pricing, cost drivers, headcount plan, tax and cash
B23: Scenario Manager | D23: Base / Optimistic / Downside levers and the live scenario control
B24: Revenue Model | D24: Customer and MRR roll-forwards, ARR waterfall, billings and deferred revenue
B25: Headcount | D25: Hiring plan, headcount and fully loaded payroll by department
B26: Operating Expenses | D26: COGS, S&M, R&D and G&A build; capex placeholder and depreciation
B27: Income Statement | D27: Monthly P&L with NOL-adjusted tax and FY2026 to FY2028 rollups
B28: Cash Flow | D28: Indirect cash flow, cash roll-forward, burn and runway
B29: KPI Dashboard | D29: Executive cards, SaaS efficiency metrics and charts
B32: MODEL CONTROL
B34: Version | D34: ="1.0" -> 1.0
B35: Prepared by | D35: ="Soban Farid" -> Soban Farid
B36: Last updated | D36: =TODAY() -> 46215
B37: Active scenario | D37: =ScenarioSel -> Base
B39: Confidential. Prepared for portfolio demonstration; all figures are illustrative.

Sheet Instructions
A1: NOVAFLOW ANALYTICS | E1: back to cover
A2: Instructions and Model Guide | E2: read this sheet first
A5: 1. THE BUSINESS
A6: NovaFlow Analytics sells workflow-analytics software to operations and finance teams that run
A7: high-volume digital processes (claims, onboarding, order-to-cash). The platform ingests event
A8: logs from CRM, ERP and ticketing systems and surfaces bottlenecks, SLA breaches and automation
A9: candidates. Founded 2022; Series B closed Nov-2025 ($18m cash into the plan).
A11: Two tiers map to two segments. Professional (mid-market, 200 to 2,000 employees) is billed
A12: monthly at circa $850 per month, sold through an inside-sales motion with short cycles and
A13: higher logo churn. Enterprise is billed annually upfront at circa $4,500 per month, sold
A14: field-led with security review, lower churn and stronger seat and module expansion. Pricing
A15: rises circa 4% per year, applied progressively as contracts renew, and expansion (seats,
A16: usage, add-on modules) is the engine behind net revenue retention above 100% in Enterprise.
A18: Go-to-market: mid-market volume drives logo growth and feeds the Enterprise pipeline;
... A43: 3. COLOUR LEGEND
A44: Hardcoded input / scenario lever | D44: 1234
A45: Formula (same sheet) | D45: =1234 -> 1234
A46: Cross-sheet link | D46: =Cover!B4 -> NOVAFLOW ANALYTICS
A47: Inputs live only on Assumptions and Scenario Manager.
A49: 4. FONTS AND COMPATIBILITY
A50: Headings: Aptos Display SemiBold. Body: Aptos. Dashboard titles: Bahnschrift SemiBold.
A51: Numbers: Aptos Narrow. On Excel versions without Aptos or Bahnschrift, substitute Arial
A52: and Arial Narrow; no layout or formula behaviour depends on the fonts.
A54: 5. VERSION 2 ROADMAP
A55: Balance Sheet (three-statement close), Working Capital (DSO/DPO and full deferred
A56: revenue balance), Capex and fixed asset schedule (replaces the capex placeholder and
A57: straight-line depreciation), Debt schedule and financing section in the Cash Flow.
A58: The Cash Flow already carries labelled placeholder lines so V2 bolts on without rework.
A61: 6. CHECKS PANEL (all must read OK)
A62: Check | D62: Value | E62: Status
A63: Scenario control is a valid scenario | D63: =IF(ISNUMBER(MATCH(ScenarioSel,ScenarioList,0)),1,0) -> 1 | E63: =IF(ISNUMBER(MATCH(ScenarioSel,ScenarioList,0)),"OK","FAIL") -> OK
A64: Income Statement revenue ties to Revenue Model | D64: =SUM('Income Statement'!AN7:AP7)-SUM('Revenue Model'!C36:AL36) -> 0 | E64: =IF(ABS(SUM('Income Statement'!AN7:AP7)-SUM('Revenue Model'!C36:AL36))<1,"OK","FAIL") -> OK
A65: OpEx payroll ties to Headcount fully loaded cost | D65: =SUM(Headcount!C34:AL34)-(SUM('Operating Expenses'!C9:AL9)+SUM('Operating Expenses'!C13:AL13)+SUM('Operating Expenses'!C20:AL20)+SUM('Operating Expenses'!C26:AL26)) -> 0 | E65: =IF(ABS(SUM(Headcount!C34:AL34)-(SUM('Operating Expenses'!C9:AL9)+SUM('Operating Expenses'!C13:AL13)+SUM('Operating Expenses'!C20:AL20)+SUM('Operating Expenses'!C26:AL26)))<1,"OK","FAIL") -> OK
A66: Closing cash ties to opening cash plus cumulative FCF | D66: ='Cash Flow'!AL21-(A_Cash0+SUM('Cash Flow'!C17:AL17)) -> 0 | E66: =IF(ABS('Cash Flow'!AL21-(A_Cash0+SUM('Cash Flow'!C17:AL17)))<1,"OK","FAIL") -> OK
A67: ARR waterfall closing ties to MRR x 12 | D67: ='Revenue Model'!AL45-'Revenue Model'!AL35 -> 0 | E67: =IF(ABS('Revenue Model'!AL45-'Revenue Model'!AL35)<1,"OK","FAIL") -> OK
A68: Tax charge never negative (NOL logic) | D68: =MIN('Income Statement'!C25:AL25) -> 0 | E68: =IF(MIN('Income Statement'!C25:AL25)>=0,"OK","FAIL") -> OK

Sheet Assumptions
A1: NOVAFLOW ANALYTICS | E1: back to cover
A2: Assumptions | E2: all static inputs; blue cells are editable
A5: MODEL SETTINGS
A6: Model start month | B6: date | C6: 46023 | I6: Month headers roll forward from this cell via EDATE.
A7: Projection horizon | B7: months | C7: 36
A9: CUSTOMER BASE AND PRICING AT DEC-2025
A10: Enterprise customers | B10: # | C10: 40 | I10: Series B scale: ~$4.0m ARR across 220 logos.
A11: Mid-market customers | B11: # | C11: 180
A12: Enterprise starting ARPU | B12: $/mo | C12: 4500 | I12: ~$54k ACV, annual upfront billing.
A13: Mid-market starting ARPU | B13: $/mo | C13: 850 | I13: ~$10k ACV, monthly billing.
A15: COST DRIVERS
A16: Hosting and infrastructure | B16: % rev | C16: 0.09 | I16: Cloud plus data pipeline; scales with usage.
A17: Customer Success allocated to COGS | B17: % | C17: 0.6 | I17: Support share of CS; remainder sits in S&M.
A18: Software and tools per head | B18: $/mo | C18: 150
A19: Rent and facilities per head | B19: $/mo | C19: 450 | I19: Facilities held in G&A (company-wide).
A20: Travel | B20: % payroll | C20: 0.02 | I20: Applied to S&M payroll; half-rate for R&D and G&A.
A21: Professional fees | B21: $/mo | C21: 30000 | I21: Audit, legal, recruitment.
A22: Professional fees growth | B22: %/yr | C22: 0.05
A23: Marketing programme growth | B23: %/yr | C23: 0.2 | I23: Applied to the scenario marketing spend from FY2027.
A25: PEOPLE COSTS
A26: Bonus | B26: % base | C26: 0.1
A27: Benefits | B27: % base | C27: 0.12
A28: Employer payroll taxes | B28: % base | C28: 0.1
A29: Fully loaded factor | B29: x | C29: =(1+A_Bonus)*(1+A_Benefits+A_PTax) -> 1.342 | I29: Formula: base x (1+bonus) x (1+benefits+payroll taxes).
A31: CAPITAL, TAX AND CASH
A32: Capex placeholder | B32: $/mo | C32: 40000 | I32: V1 placeholder; replaced by the V2 capex schedule.
A33: Depreciation life | B33: months | C33: 36 | I33: Straight line.
A34: Corporation tax rate | B34: % | C34: 0.25 | I34: Applied to cumulative pre-tax income (NOL carryforward).
A35: Opening cash, Jan-2026 | B35: $ | C35: 18000000 | I35: Series B closed Nov-2025.
A36: Opening deferred revenue | B36: $ | C36: 900000 | I36: Memo only in V1; the Cash Flow uses the monthly movement.
A38: HEADCOUNT PLAN | I38: Annual hires spread evenly across the year; the Scenario hiring pace multiplier scales them.
A39: Department | C39: Start HC | D39: Base salary | E39: 2026 | F39: 2027 | G39: 2028
A40: Engineering | C40: 12 | D40: 130000 | E40: 4 | F40: 3 | G40: 3
A41: Product | C41: 4 | D41: 120000 | E41: 1 | F41: 1 | G41: 1
A42: Sales | C42: 8 | D42: 105000 | E42: 3 | F42: 3 | G42: 3
A43: Marketing | C43: 4 | D43: 92000 | E43: 1 | F43: 1 | G43: 1
A44: Customer Success | C44: 7 | D44: 78000 | E44: 2 | F44: 3 | G44: 3
A45: G&A | C45: 5 | D45: 100000 | E45: 1 | F45: 1 | G45: 1
A47: All other figures in this workbook are formulas.

Sheet Scenario Manager
A1: NOVAFLOW ANALYTICS | E1: back to cover
A2: Scenario Manager | E2: one control cell drives the entire model
A5: SCENARIO SELECTOR
A6: Choose the active case: | C6: Base | D6: <- data-validation dropdown; every downstream formula reads the Live column
A9: Lever | B9: Unit | C9: Base | D9: Optimistic | E9: Downside | F9: Live | G9: Commercial logic
A10: New enterprise customers | B10: /mo | C10: 3 | D10: 4 | E10: 2 | F10: =_xlfn.XLOOKUP(ScenarioSel,ScenarioList,C10:E10) -> 3 | G10: Field sales capacity; ~$54k ACV each.
A11: New mid-market customers | B11: /mo | C11: 14 | D11: 18 | E11: 9 | F11: =_xlfn.XLOOKUP(ScenarioSel,ScenarioList,C11:E11) -> 14 | G11: Inside-sales volume engine; feeds Enterprise pipeline.
A12: Enterprise MRR churn | B12: %/mo | C12: 0.007 | D12: 0.005 | E12: 0.01 | F12: =_xlfn.XLOOKUP(ScenarioSel,ScenarioList,C12:E12) -> 0.007 | G12: Annual contracts and security-led lock-in keep churn low.
A13: Mid-market MRR churn | B13: %/mo | C13: 0.014 | D13: 0.012 | E13: 0.02 | F13: =_xlfn.XLOOKUP(ScenarioSel,ScenarioList,C13:E13) -> 0.014 | G13: Monthly billing and lighter onboarding mean higher churn.
A14: Enterprise expansion | B14: %/mo | C14: 0.012 | D14: 0.015 | E14: 0.008 | F14: =_xlfn.XLOOKUP(ScenarioSel,ScenarioList,C14:E14) -> 0.012 | G14: Seats, usage and modules; the NRR engine.
A15: Mid-market expansion | B15: %/mo | C15: 0.006 | D15: 0.008 | E15: 0.004 | F15: =_xlfn.XLOOKUP(ScenarioSel,ScenarioList,C15:E15) -> 0.006 | G15: Smaller accounts expand less.
A16: Annual price increase | B16: %/yr | C16: 0.04 | D16: 0.06 | E16: 0.02 | F16: =_xlfn.XLOOKUP(ScenarioSel,ScenarioList,C16:E16) -> 0.04 | G16: Applied progressively via monthly ARPU compounding.
A17: Hiring pace multiplier | B17: x | C17: 1 | D17: 1.15 | E17: 0.75 | F17: =_xlfn.XLOOKUP(ScenarioSel,ScenarioList,C17:E17) -> 1 | G17: Scales the annual hiring plan on Assumptions.
A18: Marketing programmes, FY2026 | B18: $/mo | C18: 150000 | D18: 175000 | E18: 110000 | F18: =_xlfn.XLOOKUP(ScenarioSel,ScenarioList,C18:E18) -> 150000 | G18: Grows at the marketing growth rate from FY2027.
A19: Salary inflation | B19: %/yr | C19: 0.04 | D19: 0.05 | E19: 0.03 | F19: =_xlfn.XLOOKUP(ScenarioSel,ScenarioList,C19:E19) -> 0.04 | G19: Applied each January to all salary bands.
A21: CASE NARRATIVES
A22: Base | C22: Plan of record: steady logo adds, 4% pricing, Enterprise NRR ~106% with blended NRR approaching 100% as the Enterprise mix builds, hiring to plan.
A23: Optimistic | C23: Pipeline conversion improves, pricing power holds at 6%, hiring accelerates 15% to meet demand.
A24: Downside | C24: Demand softens: fewer adds, higher churn, 2% pricing; hiring cut to 75% and marketing trimmed.

Sheet Revenue Model
A1: NOVAFLOW ANALYTICS | E1: back to cover
A2: Revenue Model | E2: customer and MRR roll-forwards, ARR waterfall, billings
A5: Month | C5: =ModelStart -> 46023 | D5: =EDATE(C5,1) -> 46054 | E5: =EDATE(D5,1) -> 46082 | F5: =EDATE(E5,1) -> 46113 | G5: =EDATE(F5,1) -> 46143 | H5: =EDATE(G5,1) -> 46174 | I5: =EDATE(H5,1) -> 46204 | J5: =EDATE(I5,1) -> 46235 | K5: =EDATE(J5,1) -> 46266 | ... AL5: =EDATE(AK5,1) -> 47088
A7: ENTERPRISE SEGMENT | Enterprise tier, annual upfront billing
A8: Opening customers | B8: # | C8: =A_EntCust0 -> 40 | D8: =C11 -> 42.72 | E8: =D11 -> 45.42096 | F8: =E11 -> 48.103013 | G8: =F11 -> 50.766292 | H8: =G11 -> 53.410928 | I8: =H11 -> 56.037052 | J8: =I11 -> 58.644792 | K8: =J11 -> 61.234279 | ... AL8: =AK11 -> 124.69672
A9: New customers | B9: # | C9: =L_NewEnt -> 3 | D9: =L_NewEnt -> 3 | E9: =L_NewEnt -> 3 | F9: =L_NewEnt -> 3 | G9: =L_NewEnt -> 3 | H9: =L_NewEnt -> 3 | I9: =L_NewEnt -> 3 | J9: =L_NewEnt -> 3 | ... AL9: =L_NewEnt -> 3
A10: Churned customers | B10: # | C10: =-C8*L_ChurnEnt -> -0.28 | D10: =-D8*L_ChurnEnt -> -0.29904 | E10: =-E8*L_ChurnEnt -> -0.31794672 | F10: =-F8*L_ChurnEnt -> -0.33672109 | G10: =-G8*L_ChurnEnt -> -0.35536405 | H10: =-H8*L_ChurnEnt -> -0.3738765 | I10: =-I8*L_ChurnEnt -> -0.39225936 | J10: =-J8*L_ChurnEnt -> -0.41051355 | ... AL10: =-AL8*L_ChurnEnt -> -0.87287701
A11: Closing customers | B11: # | C11: =C8+C9+C10 -> 42.72 | D11: =D8+D9+D10 -> 45.42096 | E11: =E8+E9+E10 -> 48.103013 | F11: =F8+F9+F10 -> 50.766292 | G11: =G8+G9+G10 -> 53.410928 | H11: =H8+H9+H10 -> 56.037052 | I11: =I8+I9+I10 -> 58.644792 | J11: =J8+J9+J10 -> 61.234279 | ... AL11: =AL8+AL9+AL10 -> 126.82384
A12: ARPU | B12: $/mo | C12: =A_EntARPU0 -> 4500 | D12: =C12*(1+L_Price)^(1/12) -> 4514.7318 | E12: =D12*(1+L_Price)^(1/12) -> 4529.5119 | F12: =E12*(1+L_Price)^(1/12) -> 4544.3403 | G12: =F12*(1+L_Price)^(1/12) -> 4559.2173 | H12: =G12*(1+L_Price)^(1/12) -> 4574.143 | I12: =H12*(1+L_Price)^(1/12) -> 4589.1176 | J12: =I12*(1+L_Price)^(1/12) -> 4604.1411 | K12: =J12*(1+L_Price)^(1/12) -> 4619.2139 | ... AL12: =AK12*(1+L_Price)^(1/12) -> 5045.3708
A14: Opening MRR | B14: $ | C14: =A_EntCust0*A_EntARPU0 -> 180000 | D14: =C18 -> 194400 | E14: =D18 -> 208916.2 | F14: =E18 -> 223549.31 | G14: =F18 -> 238300.08 | H14: =G18 -> 253169.23 | I14: =H18 -> 268157.51 | J14: =I18 -> 283265.65 | K14: =J18 -> 298494.4 | ... AL14: =AK18 -> 758107.9
A15: New business MRR | B15: $ | C15: =C9*C12 -> 13500 | D15: =D9*D12 -> 13544.195 | E15: =E9*E12 -> 13588.536 | F15: =F9*F12 -> 13633.021 | G15: =G9*G12 -> 13677.652 | H15: =H9*H12 -> 13722.429 | I15: =I9*I12 -> 13767.353 | J15: =J9*J12 -> 13812.423 | ... AL15: =AL9*AL12 -> 15136.112
A16: Expansion MRR | B16: $ | C16: =C14*L_ExpEnt -> 2160 | D16: =D14*L_ExpEnt -> 2332.8 | E16: =E14*L_ExpEnt -> 2506.9943 | F16: =F14*L_ExpEnt -> 2682.5917 | G16: =G14*L_ExpEnt -> 2859.601 | H16: =H14*L_ExpEnt -> 3038.0308 | I16: =I14*L_ExpEnt -> 3217.8901 | J16: =J14*L_ExpEnt -> 3399.1878 | ... AL16: =AL14*L_ExpEnt -> 9097.2949
A17: Churned MRR | B17: $ | C17: =-C14*L_ChurnEnt -> -1260 | D17: =-D14*L_ChurnEnt -> -1360.8 | E17: =-E14*L_ChurnEnt -> -1462.4134 | F17: =-F14*L_ChurnEnt -> -1564.8452 | G17: =-G14*L_ChurnEnt -> -1668.1006 | H17: =-H14*L_ChurnEnt -> -1772.1846 | I17: =-I14*L_ChurnEnt -> -1877.1026 | J17: =-J14*L_ChurnEnt -> -1982.8595 | ... AL17: =-AL14*L_ChurnEnt -> -5306.7553
A18: Closing MRR | B18: $ | C18: =C14+C15+C16+C17 -> 194400 | D18: =D14+D15+D16+D17 -> 208916.2 | E18: =E14+E15+E16+E17 -> 223549.31 | F18: =F14+F15+F16+F17 -> 238300.08 | G18: =G14+G15+G16+G17 -> 253169.23 | H18: =H14+H15+H16+H17 -> 268157.51 | I18: =I14+I15+I16+I17 -> 283265.65 | J18: =J14+J15+J16+J17 -> 298494.4 | ... AL18: =AL14+AL15+AL16+AL17 -> 777034.56
A20: MID-MARKET SEGMENT | Professional tier, monthly billing
A21: Opening customers | B21: # | C21: =A_MMCust0 -> 180 | D21: =C24 -> 191.48 | E21: =D24 -> 202.79928 | F21: =E24 -> 213.96009 | G21: =F24 -> 224.96465 | H21: =G24 -> 235.81514 | I21: =H24 -> 246.51373 | J21: =I24 -> 257.06254 | K21: =J24 -> 267.46366 | ... AL21: =AK24 -> 499.38267
A22: New customers | B22: # | C22: =L_NewMM -> 14 | D22: =L_NewMM -> 14 | E22: =L_NewMM -> 14 | F22: =L_NewMM -> 14 | G22: =L_NewMM -> 14 | H22: =L_NewMM -> 14 | I22: =L_NewMM -> 14 | J22: =L_NewMM -> 14 | ... AL22: =L_NewMM -> 14
A23: Churned customers | B23: # | C23: =-C21*L_ChurnMM -> -2.52 | D23: =-D21*L_ChurnMM -> -2.68072 | E23: =-E21*L_ChurnMM -> -2.8391899 | F23: =-F21*L_ChurnMM -> -2.9954413 | G23: =-G21*L_ChurnMM -> -3.1495051 | H23: =-H21*L_ChurnMM -> -3.301412 | I23: =-I21*L_ChurnMM -> -3.4511922 | J23: =-J21*L_ChurnMM -> -3.5988756 | ... AL23: =-AL21*L_ChurnMM -> -6.9913574
A24: Closing customers | B24: # | C24: =C21+C22+C23 -> 191.48 | D24: =D21+D22+D23 -> 202.79928 | E24: =E21+E22+E23 -> 213.96009 | F24: =F21+F22+F23 -> 224.96465 | G24: =G21+G22+G23 -> 235.81514 | H24: =H21+H22+H23 -> 246.51373 | I24: =I21+I22+I23 -> 257.06254 | J24: =J21+J22+J23 -> 267.46366 | ... AL24: =AL21+AL22+AL23 -> 506.39132
A25: ARPU | B25: $/mo | C25: =A_MMARPU0 -> 850 | D25: =C25*(1+L_Price)^(1/12) -> 852.78268 | E25: =D25*(1+L_Price)^(1/12) -> 855.57447 | F25: =E25*(1+L_Price)^(1/12) -> 858.3754 | G25: =F25*(1+L_Price)^(1/12) -> 861.18549 | H25: =G25*(1+L_Price)^(1/12) -> 864.00479 | I25: =H25*(1+L_Price)^(1/12) -> 866.83332 | J25: =I25*(1+L_Price)^(1/12) -> 869.6711 | K25: =J25*(1+L_Price)^(1/12) -> 872.51818 | ... AL25: =AK25*(1+L_Price)^(1/12) -> 953.01448
A27: Opening MRR | B27: $ | C27: =A_MMCust0*A_MMARPU0 -> 153000 | D27: =C31 -> 163676 | E27: =D31 -> 174305.55 | F27: =E31 -> 184889.15 | G27: =F31 -> 195427.29 | H27: =G31 -> 205920.47 | I27: =H31 -> 216369.17 | J27: =I31 -> 226773.88 | K27: =J31 -> 237135.09 | ... AL27: =AK31 -> 502110.97
A28: New business MRR | B28: $ | C28: =C22*C25 -> 11900 | D28: =D22*D25 -> 11938.958 | E28: =E22*E25 -> 11978.043 | F28: =F22*F25 -> 12017.256 | G28: =G22*G25 -> 12056.597 | H28: =H22*H25 -> 12096.067 | I28: =I22*I25 -> 12135.666 | J28: =J22*J25 -> 12175.395 | ... AL28: =AL22*AL25 -> 13342.203
A29: Expansion MRR | B29: $ | C29: =C27*L_ExpMM -> 918 | D29: =D27*L_ExpMM -> 982.056 | E29: =E27*L_ExpMM -> 1045.8333 | F29: =F27*L_ExpMM -> 1109.3349 | G29: =G27*L_ExpMM -> 1172.5637 | H29: =H27*L_ExpMM -> 1235.5228 | I29: =I27*L_ExpMM -> 1298.215 | J29: =J27*L_ExpMM -> 1360.6433 | ... AL29: =AL27*L_ExpMM -> 3012.6658
A30: Churned MRR | B30: $ | C30: =-C27*L_ChurnMM -> -2142 | D30: =-D27*L_ChurnMM -> -2291.464 | E30: =-E27*L_ChurnMM -> -2440.2777 | F30: =-F27*L_ChurnMM -> -2588.4481 | G30: =-G27*L_ChurnMM -> -2735.9821 | H30: =-H27*L_ChurnMM -> -2882.8866 | I30: =-I27*L_ChurnMM -> -3029.1684 | J30: =-J27*L_ChurnMM -> -3174.8344 | ... AL30: =-AL27*L_ChurnMM -> -7029.5536
A31: Closing MRR | B31: $ | C31: =C27+C28+C29+C30 -> 163676 | D31: =D27+D28+D29+D30 -> 174305.55 | E31: =E27+E28+E29+E30 -> 184889.15 | F31: =F27+F28+F29+F30 -> 195427.29 | G31: =G27+G28+G29+G30 -> 205920.47 | H31: =H27+H28+H29+H30 -> 216369.17 | I31: =I27+I28+I29+I30 -> 226773.88 | J31: =J27+J28+J29+J30 -> 237135.09 | ... AL31: =AL27+AL28+AL29+AL30 -> 511436.29
A33: TOTAL AND RECOGNISED REVENUE
A34: Total MRR | B34: $ | C34: =C18+C31 -> 358076 | D34: =D18+D31 -> 383221.74 | E34: =E18+E31 -> 408438.46 | F34: =F18+F31 -> 433727.37 | G34: =G18+G31 -> 459089.7 | H34: =H18+H31 -> 484526.68 | I34: =I18+I31 -> 510039.53 | J34: =J18+J31 -> 535629.49 | ... AL34: =AL18+AL31 -> 1288470.8
A35: Total ARR | B35: $ | C35: =C34*12 -> 4296912 | D35: =D34*12 -> 4598660.9 | E35: =E34*12 -> 4901261.5 | F35: =F34*12 -> 5204728.4 | G35: =G34*12 -> 5509076.4 | H35: =H34*12 -> 5814320.1 | I35: =I34*12 -> 6120474.4 | J35: =J34*12 -> 6427553.9 | ... AL35: =AL34*12 -> 15461650
A36: Recognised revenue | B36: $ | C36: =C34 -> 358076 | D36: =D34 -> 383221.74 | E36: =E34 -> 408438.46 | F36: =F34 -> 433727.37 | G36: =G34 -> 459089.7 | H36: =H34 -> 484526.68 | I36: =I34 -> 510039.53 | J36: =J34 -> 535629.49 | ... AL36: =AL34 -> 1288470.8
A37: of which Enterprise tier | B37: $ | C37: =C18 -> 194400 | D37: =D18 -> 208916.2 | E37: =E18 -> 223549.31 | F37: =F18 -> 238300.08 | G37: =G18 -> 253169.23 | H37: =H18 -> 268157.51 | I37: =I18 -> 283265.65 | J37: =J18 -> 298494.4 | ... AL37: =AL18 -> 777034.56
A38: of which Professional tier | B38: $ | C38: =C31 -> 163676 | D38: =D31 -> 174305.55 | E38: =E31 -> 184889.15 | F38: =F31 -> 195427.29 | G38: =G31 -> 205920.47 | H38: =H31 -> 216369.17 | I38: =I31 -> 226773.88 | J38: =J31 -> 237135.09 | ... AL38: =AL31 -> 511436.29
A40: ARR GROWTH WATERFALL
A41: Opening ARR | B41: $ | C41: =(C14+C27)*12 -> 3996000 | D41: =(D14+D27)*12 -> 4296912 | E41: =(E14+E27)*12 -> 4598660.9 | F41: =(F14+F27)*12 -> 4901261.5 | G41: =(G14+G27)*12 -> 5204728.4 | H41: =(H14+H27)*12 -> 5509076.4 | I41: =(I14+I27)*12 -> 5814320.1 | J41: =(J14+J27)*12 -> 6120474.4 | ... AL41: =(AL14+AL27)*12 -> 15122627
A42: New business ARR | B42: $ | C42: =(C15+C28)*12 -> 304800 | D42: =(D15+D28)*12 -> 305797.84 | E42: =(E15+E28)*12 -> 306798.94 | F42: =(F15+F28)*12 -> 307803.32 | G42: =(G15+G28)*12 -> 308810.99 | H42: =(H15+H28)*12 -> 309821.95 | I42: =(I15+I28)*12 -> 310836.23 | J42: =(J15+J28)*12 -> 311853.83 | ... AL42: =(AL15+AL28)*12 -> 341739.78
A43: Expansion ARR | B43: $ | C43: =(C16+C29)*12 -> 36936 | D43: =(D16+D29)*12 -> 39778.272 | E43: =(E16+E29)*12 -> 42633.932 | F43: =(F16+F29)*12 -> 45503.12 | G43: =(G16+G29)*12 -> 48385.976 | H43: =(H16+H29)*12 -> 51282.643 | I43: =(I16+I29)*12 -> 54193.261 | J43: =(J16+J29)*12 -> 57117.973 | ... AL43: =(AL16+AL29)*12 -> 145319.53
A44: Churned ARR | B44: $ | C44: =(C17+C30)*12 -> -40824 | D44: =(D17+D30)*12 -> -43827.168 | E44: =(E17+E30)*12 -> -46832.293 | F44: =(F17+F30)*12 -> -49839.519 | G44: =(G17+G30)*12 -> -52848.991 | H44: =(H17+H30)*12 -> -55860.854 | I44: =(I17+I30)*12 -> -58875.251 | J44: =(J17+J30)*12 -> -61892.327 | ... AL44: =(AL17+AL30)*12 -> -148035.71
A45: Closing ARR | B45: $ | C45: =C41+C42+C43+C44 -> 4296912 | D45: =D41+D42+D43+D44 -> 4598660.9 | E45: =E41+E42+E43+E44 -> 4901261.5 | F45: =F41+F42+F43+F44 -> 5204728.4 | G45: =G41+G42+G43+G44 -> 5509076.4 | H45: =H41+H42+H43+H44 -> 5814320.1 | I45: =I41+I42+I43+I44 -> 6120474.4 | J45: =J41+J42+J43+J44 -> 6427553.9 | ... AL45: =AL41+AL42+AL43+AL44 -> 15461650
A47: BILLINGS AND DEFERRED REVENUE | feeds the Cash Flow
A48: Mid-market billings (monthly) | B48: $ | C48: =C31 -> 163676 | D48: =D31 -> 174305.55 | E48: =E31 -> 184889.15 | F48: =F31 -> 195427.29 | G48: =G31 -> 205920.47 | H48: =H31 -> 216369.17 | I48: =I31 -> 226773.88 | J48: =J31 -> 237135.09 | ... AL48: =AL31 -> 511436.29
A49: Enterprise billings (annual upfront) | B49: $ | C49: =C15*12+(C14+C16+C17) -> 342900 | D49: =D15*12+(D14+D16+D17) -> 357902.35 | E49: =E15*12+(E14+E16+E17) -> 373023.2 | F49: =F15*12+(F14+F16+F17) -> 388263.31 | G49: =G15*12+(G14+G16+G17) -> 403623.4 | H49: =H15*12+(H14+H16+H17) -> 419104.23 | I49: =I15*12+(I14+I16+I17) -> 434706.53 | J49: =J15*12+(J14+J16+J17) -> 450431.06 | ... AL49: =AL15*12+(AL14+AL16+AL17) -> 943531.79
...

Sheet Headcount
A1: NOVAFLOW ANALYTICS | E1: back to cover
A2: Headcount and Payroll | E2: hiring plan, headcount and fully loaded cost by department
A5: Month | C5: =ModelStart -> 46023 | D5: =EDATE(C5,1) -> 46054 | E5: =EDATE(D5,1) -> 46082 | F5: =EDATE(E5,1) -> 46113 | G5: =EDATE(F5,1) -> 46143 | H5: =EDATE(G5,1) -> 46174 | I5: =EDATE(H5,1) -> 46204 | J5: =EDATE(I5,1) -> 46235 | K5: =EDATE(J5,1) -> 46266 | ... AL5: =EDATE(AK5,1) -> 47088
A7: HIRES PER MONTH | annual plan / 12 x scenario hiring pace
A8: Engineering | B8: # | C8: =_xlfn.XLOOKUP(YEAR(C$5),A_HireYears,_xlfn.XLOOKUP($A8,A_DeptNames,A_DeptHires))/12*L_HirePace -> 0.33333333 | D8: =_xlfn.XLOOKUP(YEAR(D$5),A_HireYears,_xlfn.XLOOKUP($A8,A_DeptNames,A_DeptHires))/12*L_HirePace -> 0.33333333 | E8: =_xlfn.XLOOKUP(YEAR(E$5),A_HireYears,_xlfn.XLOOKUP($A8,A_DeptNames,A_DeptHires))/12*L_HirePace -> 0.33333333 | F8: =_xlfn.XLOOKUP(YEAR(F$5),A_HireYears,_xlfn.XLOOKUP($A8,A_DeptNames,A_DeptHires))/12*L_HirePace -> 0.33333333 | G8: =_xlfn.XLOOKUP(YEAR(G$5),A_HireYears,_xlfn.XLOOKUP($A8,A_DeptNames,A_DeptHires))/12*L_HirePace -> 0.33333333 | H8: =_xlfn.XLOOKUP(YEAR(H$5),A_HireYears,_xlfn.XLOOKUP($A8,A_DeptNames,A_DeptHires))/12*L_HirePace -> 0.33333333 | I8: =_xlfn.XLOOKUP(YEAR(I$5),A_HireYears,_xlfn.XLOOKUP($A8,A_DeptNames,A_DeptHires))/12*L_HirePace -> 0.33333333 | J8: =_xlfn.XLOOKUP(YEAR(J$5),A_HireYears,_xlfn.XLOOKUP($A8,A_DeptNames,A_DeptHires))/12*L_HirePace -> 0.33333333 | ... AL8: =_xlfn.XLOOKUP(YEAR(AL$5),A_HireYears,_xlfn.XLOOKUP($A8,A_DeptNames,A_DeptHires))/12*L_HirePace -> 0.25
A9: Product | B9: # | C9: =_xlfn.XLOOKUP(YEAR(C$5),A_HireYears,_xlfn.XLOOKUP($A9,A_DeptNames,A_DeptHires))/12*L_HirePace -> 0.083333333 | D9: =_xlfn.XLOOKUP(YEAR(D$5),A_HireYears,_xlfn.XLOOKUP($A9,A_DeptNames,A_DeptHires))/12*L_HirePace -> 0.083333333 | E9: =_xlfn.XLOOKUP(YEAR(E$5),A_HireYears,_xlfn.XLOOKUP($A9,A_DeptNames,A_DeptHires))/12*L_HirePace -> 0.083333333 | F9: =_xlfn.XLOOKUP(YEAR(F$5),A_HireYears,_xlfn.XLOOKUP($A9,A_DeptNames,A_DeptHires))/12*L_HirePace -> 0.083333333 | G9: =_xlfn.XLOOKUP(YEAR(G$5),A_HireYears,_xlfn.XLOOKUP($A9,A_DeptNames,A_DeptHires))/12*L_HirePace -> 0.083333333 | H9: =_xlfn.XLOOKUP(YEAR(H$5),A_HireYears,_xlfn.XLOOKUP($A9,A_DeptNames,A_DeptHires))/12*L_HirePace -> 0.083333333 | I9: =_xlfn.XLOOKUP(YEAR(I$5),A_HireYears,_xlfn.XLOOKUP($A9,A_DeptNames,A_DeptHires))/12*L_HirePace -> 0.083333333 | J9: =_xlfn.XLOOKUP(YEAR(J$5),A_HireYears,_xlfn.XLOOKUP($A9,A_DeptNames,A_DeptHires))/12*L_HirePace -> 0.083333333 | ... AL9: =_xlfn.XLOOKUP(YEAR(AL$5),A_HireYears,_xlfn.XLOOKUP($A9,A_DeptNames,A_DeptHires))/12*L_HirePace -> 0.083333333
A10: Sales | B10: # | C10: =_xlfn.XLOOKUP(YEAR(C$5),A_HireYears,_xlfn.XLOOKUP($A10,A_DeptNames,A_DeptHires))/12*L_HirePace -> 0.25 | D10: =_xlfn.XLOOKUP(YEAR(D$5),A_HireYears,_xlfn.XLOOKUP($A10,A_DeptNames,A_DeptHires))/12*L_HirePace -> 0.25 | E10: =_xlfn.XLOOKUP(YEAR(E$5),A_HireYears,_xlfn.XLOOKUP($A10,A_DeptNames,A_DeptHires))/12*L_HirePace -> 0.25 | F10: =_xlfn.XLOOKUP(YEAR(F$5),A_HireYears,_xlfn.XLOOKUP($A10,A_DeptNames,A_DeptHires))/12*L_HirePace -> 0.25 | G10: =_xlfn.XLOOKUP(YEAR(G$5),A_HireYears,_xlfn.XLOOKUP($A10,A_DeptNames,A_DeptHires))/12*L_HirePace -> 0.25 | H10: =_xlfn.XLOOKUP(YEAR(H$5),A_HireYears,_xlfn.XLOOKUP($A10,A_DeptNames,A_DeptHires))/12*L_HirePace -> 0.25 | I10: =_xlfn.XLOOKUP(YEAR(I$5),A_HireYears,_xlfn.XLOOKUP($A10,A_DeptNames,A_DeptHires))/12*L_HirePace -> 0.25 | J10: =_xlfn.XLOOKUP(YEAR(J$5),A_HireYears,_xlfn.XLOOKUP($A10,A_DeptNames,A_DeptHires))/12*L_HirePace -> 0.25 | ... AL10: =_xlfn.XLOOKUP(YEAR(AL$5),A_HireYears,_xlfn.XLOOKUP($A10,A_DeptNames,A_DeptHires))/12*L_HirePace -> 0.25
A11: Marketing | B11: # | C11: =_xlfn.XLOOKUP(YEAR(C$5),A_HireYears,_xlfn.XLOOKUP($A11,A_DeptNames,A_DeptHires))/12*L_HirePace -> 0.083333333 | D11: =_xlfn.XLOOKUP(YEAR(D$5),A_HireYears,_xlfn.XLOOKUP($A11,A_DeptNames,A_DeptHires))/12*L_HirePace -> 0.083333333 | E11: =_xlfn.XLOOKUP(YEAR(E$5),A_HireYears,_xlfn.XLOOKUP($A11,A_DeptNames,A_DeptHires))/12*L_HirePace -> 0.083333333 | F11: =_xlfn.XLOOKUP(YEAR(F$5),A_HireYears,_xlfn.XLOOKUP($A11,A_DeptNames,A_DeptHires))/12*L_HirePace -> 0.083333333 | G11: =_xlfn.XLOOKUP(YEAR(G$5),A_HireYears,_xlfn.XLOOKUP($A11,A_DeptNames,A_DeptHires))/12*L_HirePace -> 0.083333333 | H11: =_xlfn.XLOOKUP(YEAR(H$5),A_HireYears,_xlfn.XLOOKUP($A11,A_DeptNames,A_DeptHires))/12*L_HirePace -> 0.083333333 | I11: =_xlfn.XLOOKUP(YEAR(I$5),A_HireYears,_xlfn.XLOOKUP($A11,A_DeptNames,A_DeptHires))/12*L_HirePace -> 0.083333333 | J11: =_xlfn.XLOOKUP(YEAR(J$5),A_HireYears,_xlfn.XLOOKUP($A11,A_DeptNames,A_DeptHires))/12*L_HirePace -> 0.083333333 | ... AL11: =_xlfn.XLOOKUP(YEAR(AL$5),A_HireYears,_xlfn.XLOOKUP($A11,A_DeptNames,A_DeptHires))/12*L_HirePace -> 0.083333333
A12: Customer Success | B12: # | C12: =_xlfn.XLOOKUP(YEAR(C$5),A_HireYears,_xlfn.XLOOKUP($A12,A_DeptNames,A_DeptHires))/12*L_HirePace -> 0.16666667 | D12: =_xlfn.XLOOKUP(YEAR(D$5),A_HireYears,_xlfn.XLOOKUP($A12,A_DeptNames,A_DeptHires))/12*L_HirePace -> 0.16666667 | E12: =_xlfn.XLOOKUP(YEAR(E$5),A_HireYears,_xlfn.XLOOKUP($A12,A_DeptNames,A_DeptHires))/12*L_HirePace -> 0.16666667 | F12: =_xlfn.XLOOKUP(YEAR(F$5),A_HireYears,_xlfn.XLOOKUP($A12,A_DeptNames,A_DeptHires))/12*L_HirePace -> 0.16666667 | G12: =_xlfn.XLOOKUP(YEAR(G$5),A_HireYears,_xlfn.XLOOKUP($A12,A_DeptNames,A_DeptHires))/12*L_HirePace -> 0.16666667 | H12: =_xlfn.XLOOKUP(YEAR(H$5),A_HireYears,_xlfn.XLOOKUP($A12,A_DeptNames,A_DeptHires))/12*L_HirePace -> 0.16666667 | I12: =_xlfn.XLOOKUP(YEAR(I$5),A_HireYears,_xlfn.XLOOKUP($A12,A_DeptNames,A_DeptHires))/12*L_HirePace -> 0.16666667 | J12: =_xlfn.XLOOKUP(YEAR(J$5),A_HireYears,_xlfn.XLOOKUP($A12,A_DeptNames,A_DeptHires))/12*L_HirePace -> 0.16666667 | ... AL12: =_xlfn.XLOOKUP(YEAR(AL$5),A_HireYears,_xlfn.XLOOKUP($A12,A_DeptNames,A_DeptHires))/12*L_HirePace -> 0.25
A13: G&A | B13: # | C13: =_xlfn.XLOOKUP(YEAR(C$5),A_HireYears,_xlfn.XLOOKUP($A13,A_DeptNames,A_DeptHires))/12*L_HirePace -> 0.083333333 | D13: =_xlfn.XLOOKUP(YEAR(D$5),A_HireYears,_xlfn.XLOOKUP($A13,A_DeptNames,A_DeptHires))/12*L_HirePace -> 0.083333333 | E13: =_xlfn.XLOOKUP(YEAR(E$5),A_HireYears,_xlfn.XLOOKUP($A13,A_DeptNames,A_DeptHires))/12*L_HirePace -> 0.083333333 | F13: =_xlfn.XLOOKUP(YEAR(F$5),A_HireYears,_xlfn.XLOOKUP($A13,A_DeptNames,A_DeptHires))/12*L_HirePace -> 0.083333333 | G13: =_xlfn.XLOOKUP(YEAR(G$5),A_HireYears,_xlfn.XLOOKUP($A13,A_DeptNames,A_DeptHires))/12*L_HirePace -> 0.083333333 | H13: =_xlfn.XLOOKUP(YEAR(H$5),A_HireYears,_xlfn.XLOOKUP($A13,A_DeptNames,A_DeptHires))/12*L_HirePace -> 0.083333333 | I13: =_xlfn.XLOOKUP(YEAR(I$5),A_HireYears,_xlfn.XLOOKUP($A13,A_DeptNames,A_DeptHires))/12*L_HirePace -> 0.083333333 | J13: =_xlfn.XLOOKUP(YEAR(J$5),A_HireYears,_xlfn.XLOOKUP($A13,A_DeptNames,A_DeptHires))/12*L_HirePace -> 0.083333333 | ... AL13: =_xlfn.XLOOKUP(YEAR(AL$5),A_HireYears,_xlfn.XLOOKUP($A13,A_DeptNames,A_DeptHires))/12*L_HirePace -> 0.083333333
A15: HEADCOUNT | end of month
A16: Engineering | B16: # | C16: =_xlfn.XLOOKUP($A16,A_DeptNames,A_DeptStart)+C8 -> 12.333333 | D16: =C16+D8 -> 12.666667 | E16: =D16+E8 -> 13 | F16: =E16+F8 -> 13.333333 | G16: =F16+G8 -> 13.666667 | H16: =G16+H8 -> 14 | I16: =H16+I8 -> 14.333333 | J16: =I16+J8 -> 14.666667 | K16: =J16+K8 -> 15 | ... AL16: =AK16+AL8 -> 22
A17: Product | B17: # | C17: =_xlfn.XLOOKUP($A17,A_DeptNames,A_DeptStart)+C9 -> 4.0833333 | D17: =C17+D9 -> 4.1666667 | E17: =D17+E9 -> 4.25 | F17: =E17+F9 -> 4.3333333 | G17: =F17+G9 -> 4.4166667 | H17: =G17+H9 -> 4.5 | I17: =H17+I9 -> 4.5833333 | J17: =I17+J9 -> 4.6666667 | K17: =J17+K9 -> 4.75 | ... AL17: =AK17+AL9 -> 7
A18: Sales | B18: # | C18: =_xlfn.XLOOKUP($A18,A_DeptNames,A_DeptStart)+C10 -> 8.25 | D18: =C18+D10 -> 8.5 | E18: =D18+E10 -> 8.75 | F18: =E18+F10 -> 9 | G18: =F18+G10 -> 9.25 | H18: =G18+H10 -> 9.5 | I18: =H18+I10 -> 9.75 | J18: =I18+J10 -> 10 | K18: =J18+K10 -> 10.25 | ... AL18: =AK18+AL10 -> 17
A19: Marketing | B19: # | C19: =_xlfn.XLOOKUP($A19,A_DeptNames,A_DeptStart)+C11 -> 4.0833333 | D19: =C19+D11 -> 4.1666667 | E19: =D19+E11 -> 4.25 | F19: =E19+F11 -> 4.3333333 | G19: =F19+G11 -> 4.4166667 | H19: =G19+H11 -> 4.5 | I19: =H19+I11 -> 4.5833333 | J19: =I19+J11 -> 4.6666667 | K19: =J19+K11 -> 4.75 | ... AL19: =AK19+AL11 -> 7
A20: Customer Success | B20: # | C20: =_xlfn.XLOOKUP($A20,A_DeptNames,A_DeptStart)+C12 -> 7.1666667 | D20: =C20+D12 -> 7.3333333 | E20: =D20+E12 -> 7.5 | F20: =E20+F12 -> 7.6666667 | G20: =F20+G12 -> 7.8333333 | H20: =G20+H12 -> 8 | I20: =H20+I12 -> 8.1666667 | J20: =I20+J12 -> 8.3333333 | K20: =J20+K12 -> 8.5 | ... AL20: =AK20+AL12 -> 15
A21: G&A | B21: # | C21: =_xlfn.XLOOKUP($A21,A_DeptNames,A_DeptStart)+C13 -> 5.0833333 | D21: =C21+D13 -> 5.1666667 | E21: =D21+E13 -> 5.25 | F21: =E21+F13 -> 5.3333333 | G21: =F21+G13 -> 5.4166667 | H21: =G21+H13 -> 5.5 | I21: =H21+I13 -> 5.5833333 | J21: =I21+J13 -> 5.6666667 | K21: =J21+K13 -> 5.75 | ... AL21: =AK21+AL13 -> 8
A22: Total headcount | B22: # | C22: =SUM(C16:C21) -> 41 | D22: =SUM(D16:D21) -> 42 | E22: =SUM(E16:E21) -> 43 | F22: =SUM(F16:F21) -> 44 | G22: =SUM(G16:G21) -> 45 | H22: =SUM(H16:H21) -> 46 | I22: =SUM(I16:I21) -> 47 | J22: =SUM(J16:J21) -> 48 | ... AL22: =SUM(AL16:AL21) -> 76
A24: SALARY INFLATION
A25: Salary index (applied each January) | B25: x | C25: =(1+L_SalInfl)^(YEAR(C$5)-2026) -> 1 | D25: =(1+L_SalInfl)^(YEAR(D$5)-2026) -> 1 | E25: =(1+L_SalInfl)^(YEAR(E$5)-2026) -> 1 | F25: =(1+L_SalInfl)^(YEAR(F$5)-2026) -> 1 | G25: =(1+L_SalInfl)^(YEAR(G$5)-2026) -> 1 | H25: =(1+L_SalInfl)^(YEAR(H$5)-2026) -> 1 | I25: =(1+L_SalInfl)^(YEAR(I$5)-2026) -> 1 | J25: =(1+L_SalInfl)^(YEAR(J$5)-2026) -> 1 | ... AL25: =(1+L_SalInfl)^(YEAR(AL$5)-2026) -> 1.0816
A27: FULLY LOADED COST PER MONTH | base x inflation x loaded factor
A28: Engineering | B28: $ | C28: =C16*_xlfn.XLOOKUP($A28,A_DeptNames,A_DeptSal)*C$25*A_Load/12 -> 179306.11 | D28: =D16*_xlfn.XLOOKUP($A28,A_DeptNames,A_DeptSal)*D$25*A_Load/12 -> 184152.22 | E28: =E16*_xlfn.XLOOKUP($A28,A_DeptNames,A_DeptSal)*E$25*A_Load/12 -> 188998.33 | F28: =F16*_xlfn.XLOOKUP($A28,A_DeptNames,A_DeptSal)*F$25*A_Load/12 -> 193844.44 | G28: =G16*_xlfn.XLOOKUP($A28,A_DeptNames,A_DeptSal)*G$25*A_Load/12 -> 198690.56 | H28: =H16*_xlfn.XLOOKUP($A28,A_DeptNames,A_DeptSal)*H$25*A_Load/12 -> 203536.67 | I28: =I16*_xlfn.XLOOKUP($A28,A_DeptNames,A_DeptSal)*I$25*A_Load/12 -> 208382.78 | J28: =J16*_xlfn.XLOOKUP($A28,A_DeptNames,A_DeptSal)*J$25*A_Load/12 -> 213228.89 | ... AL28: =AL16*_xlfn.XLOOKUP($A28,A_DeptNames,A_DeptSal)*AL$25*A_Load/12 -> 345942.55
A29: Product | B29: $ | C29: =C17*_xlfn.XLOOKUP($A29,A_DeptNames,A_DeptSal)*C$25*A_Load/12 -> 54798.333 | D29: =D17*_xlfn.XLOOKUP($A29,A_DeptNames,A_DeptSal)*D$25*A_Load/12 -> 55916.667 | E29: =E17*_xlfn.XLOOKUP($A29,A_DeptNames,A_DeptSal)*E$25*A_Load/12 -> 57035 | F29: =F17*_xlfn.XLOOKUP($A29,A_DeptNames,A_DeptSal)*F$25*A_Load/12 -> 58153.333 | G29: =G17*_xlfn.XLOOKUP($A29,A_DeptNames,A_DeptSal)*G$25*A_Load/12 -> 59271.667 | H29: =H17*_xlfn.XLOOKUP($A29,A_DeptNames,A_DeptSal)*H$25*A_Load/12 -> 60390 | I29: =I17*_xlfn.XLOOKUP($A29,A_DeptNames,A_DeptSal)*I$25*A_Load/12 -> 61508.333 | J29: =J17*_xlfn.XLOOKUP($A29,A_DeptNames,A_DeptSal)*J$25*A_Load/12 -> 62626.667 | ... AL29: =AL17*_xlfn.XLOOKUP($A29,A_DeptNames,A_DeptSal)*AL$25*A_Load/12 -> 101605.5
A30: Sales | B30: $ | C30: =C18*_xlfn.XLOOKUP($A30,A_DeptNames,A_DeptSal)*C$25*A_Load/12 -> 96875.625 | D30: =D18*_xlfn.XLOOKUP($A30,A_DeptNames,A_DeptSal)*D$25*A_Load/12 -> 99811.25 | E30: =E18*_xlfn.XLOOKUP($A30,A_DeptNames,A_DeptSal)*E$25*A_Load/12 -> 102746.88 | F30: =F18*_xlfn.XLOOKUP($A30,A_DeptNames,A_DeptSal)*F$25*A_Load/12 -> 105682.5 | G30: =G18*_xlfn.XLOOKUP($A30,A_DeptNames,A_DeptSal)*G$25*A_Load/12 -> 108618.13 | H30: =H18*_xlfn.XLOOKUP($A30,A_DeptNames,A_DeptSal)*H$25*A_Load/12 -> 111553.75 | I30: =I18*_xlfn.XLOOKUP($A30,A_DeptNames,A_DeptSal)*I$25*A_Load/12 -> 114489.38 | J30: =J18*_xlfn.XLOOKUP($A30,A_DeptNames,A_DeptSal)*J$25*A_Load/12 -> 117425 | ... AL30: =AL18*_xlfn.XLOOKUP($A30,A_DeptNames,A_DeptSal)*AL$25*A_Load/12 -> 215911.7
A31: Marketing | B31: $ | C31: =C19*_xlfn.XLOOKUP($A31,A_DeptNames,A_DeptSal)*C$25*A_Load/12 -> 42012.056 | D31: =D19*_xlfn.XLOOKUP($A31,A_DeptNames,A_DeptSal)*D$25*A_Load/12 -> 42869.444 | E31: =E19*_xlfn.XLOOKUP($A31,A_DeptNames,A_DeptSal)*E$25*A_Load/12 -> 43726.833 | F31: =F19*_xlfn.XLOOKUP($A31,A_DeptNames,A_DeptSal)*F$25*A_Load/12 -> 44584.222 | G31: =G19*_xlfn.XLOOKUP($A31,A_DeptNames,A_DeptSal)*G$25*A_Load/12 -> 45441.611 | H31: =H19*_xlfn.XLOOKUP($A31,A_DeptNames,A_DeptSal)*H$25*A_Load/12 -> 46299 | I31: =I19*_xlfn.XLOOKUP($A31,A_DeptNames,A_DeptSal)*I$25*A_Load/12 -> 47156.389 | J31: =J19*_xlfn.XLOOKUP($A31,A_DeptNames,A_DeptSal)*J$25*A_Load/12 -> 48013.778 | ... AL31: =AL19*_xlfn.XLOOKUP($A31,A_DeptNames,A_DeptSal)*AL$25*A_Load/12 -> 77897.553
A32: Customer Success | B32: $ | C32: =C20*_xlfn.XLOOKUP($A32,A_DeptNames,A_DeptSal)*C$25*A_Load/12 -> 62514.833 | D32: =D20*_xlfn.XLOOKUP($A32,A_DeptNames,A_DeptSal)*D$25*A_Load/12 -> 63968.667 | E32: =E20*_xlfn.XLOOKUP($A32,A_DeptNames,A_DeptSal)*E$25*A_Load/12 -> 65422.5 | F32: =F20*_xlfn.XLOOKUP($A32,A_DeptNames,A_DeptSal)*F$25*A_Load/12 -> 66876.333 | G32: =G20*_xlfn.XLOOKUP($A32,A_DeptNames,A_DeptSal)*G$25*A_Load/12 -> 68330.167 | H32: =H20*_xlfn.XLOOKUP($A32,A_DeptNames,A_DeptSal)*H$25*A_Load/12 -> 69784 | I32: =I20*_xlfn.XLOOKUP($A32,A_DeptNames,A_DeptSal)*I$25*A_Load/12 -> 71237.833 | J32: =J20*_xlfn.XLOOKUP($A32,A_DeptNames,A_DeptSal)*J$25*A_Load/12 -> 72691.667 | ... AL32: =AL20*_xlfn.XLOOKUP($A32,A_DeptNames,A_DeptSal)*AL$25*A_Load/12 -> 141521.95
A33: G&A | B33: $ | C33: =C21*_xlfn.XLOOKUP($A33,A_DeptNames,A_DeptSal)*C$25*A_Load/12 -> 56848.611 | D33: =D21*_xlfn.XLOOKUP($A33,A_DeptNames,A_DeptSal)*D$25*A_Load/12 -> 57780.556 | E33: =E21*_xlfn.XLOOKUP($A33,A_DeptNames,A_DeptSal)*E$25*A_Load/12 -> 58712.5 | F33: =F21*_xlfn.XLOOKUP($A33,A_DeptNames,A_DeptSal)*F$25*A_Load/12 -> 59644.444 | G33: =G21*_xlfn.XLOOKUP($A33,A_DeptNames,A_DeptSal)*G$25*A_Load/12 -> 60576.389 | H33: =H21*_xlfn.XLOOKUP($A33,A_DeptNames,A_DeptSal)*H$25*A_Load/12 -> 61508.333 | I33: =I21*_xlfn.XLOOKUP($A33,A_DeptNames,A_DeptSal)*I$25*A_Load/12 -> 62440.278 | J33: =J21*_xlfn.XLOOKUP($A33,A_DeptNames,A_DeptSal)*J$25*A_Load/12 -> 63372.222 | ... AL33: =AL21*_xlfn.XLOOKUP($A33,A_DeptNames,A_DeptSal)*AL$25*A_Load/12 -> 96767.147
A34: Total fully loaded payroll | B34: $ | C34: =SUM(C28:C33) -> 492355.57 | D34: =SUM(D28:D33) -> 504498.81 | E34: =SUM(E28:E33) -> 516642.04 | F34: =SUM(F28:F33) -> 528785.28 | G34: =SUM(G28:G33) -> 540928.51 | H34: =SUM(H28:H33) -> 553071.75 | I34: =SUM(I28:I33) -> 565214.99 | J34: =SUM(J28:J33) -> 577358.22 | ... AL34: =SUM(AL28:AL33) -> 979646.4
A36: Feeds the payroll lines on Operating Expenses by formula. Customer Success is split between COGS (support) and S&M on the Operating Expenses sheet.

Sheet Operating Expenses
A1: NOVAFLOW ANALYTICS | E1: back to cover
A2: Operating Expenses | E2: COGS, S&M, R&D, G&A; capex placeholder and depreciation
A5: Month | C5: =ModelStart -> 46023 | D5: =EDATE(C5,1) -> 46054 | E5: =EDATE(D5,1) -> 46082 | F5: =EDATE(E5,1) -> 46113 | G5: =EDATE(F5,1) -> 46143 | H5: =EDATE(G5,1) -> 46174 | I5: =EDATE(H5,1) -> 46204 | J5: =EDATE(I5,1) -> 46235 | K5: =EDATE(J5,1) -> 46266 | ... AL5: =EDATE(AK5,1) -> 47088
A7: COST OF GOODS SOLD
A8: Hosting and infrastructure | B8: $ | C8: =A_HostPct*'Revenue Model'!C36 -> 32226.84 | D8: =A_HostPct*'Revenue Model'!D36 -> 34489.957 | E8: =A_HostPct*'Revenue Model'!E36 -> 36759.461 | F8: =A_HostPct*'Revenue Model'!F36 -> 39035.463 | G8: =A_HostPct*'Revenue Model'!G36 -> 41318.073 | H8: =A_HostPct*'Revenue Model'!H36 -> 43607.401 | I8: =A_HostPct*'Revenue Model'!I36 -> 45903.558 | J8: =A_HostPct*'Revenue Model'!J36 -> 48206.654 | ... AL8: =A_HostPct*'Revenue Model'!AL36 -> 115962.38
A9: Support payroll (CS share) | B9: $ | C9: =A_CSCogs*Headcount!C32 -> 37508.9 | D9: =A_CSCogs*Headcount!D32 -> 38381.2 | E9: =A_CSCogs*Headcount!E32 -> 39253.5 | F9: =A_CSCogs*Headcount!F32 -> 40125.8 | G9: =A_CSCogs*Headcount!G32 -> 40998.1 | H9: =A_CSCogs*Headcount!H32 -> 41870.4 | I9: =A_CSCogs*Headcount!I32 -> 42742.7 | J9: =A_CSCogs*Headcount!J32 -> 43615 | ... AL9: =A_CSCogs*Headcount!AL32 -> 84913.171
A10: Total COGS | B10: $ | C10: =C8+C9 -> 69735.74 | D10: =D8+D9 -> 72871.157 | E10: =E8+E9 -> 76012.961 | F10: =F8+F9 -> 79161.263 | G10: =G8+G9 -> 82316.173 | H10: =H8+H9 -> 85477.801 | I10: =I8+I9 -> 88646.258 | J10: =J8+J9 -> 91821.654 | ... AL10: =AL8+AL9 -> 200875.55
A12: SALES AND MARKETING
A13: Payroll (Sales, Marketing, CS share) | B13: $ | C13: =Headcount!C30+Headcount!C31+(1-A_CSCogs)*Headcount!C32 -> 163893.61 | D13: =Headcount!D30+Headcount!D31+(1-A_CSCogs)*Headcount!D32 -> 168268.16 | E13: =Headcount!E30+Headcount!E31+(1-A_CSCogs)*Headcount!E32 -> 172642.71 | F13: =Headcount!F30+Headcount!F31+(1-A_CSCogs)*Headcount!F32 -> 177017.26 | G13: =Headcount!G30+Headcount!G31+(1-A_CSCogs)*Headcount!G32 -> 181391.8 | H13: =Headcount!H30+Headcount!H31+(1-A_CSCogs)*Headcount!H32 -> 185766.35 | I13: =Headcount!I30+Headcount!I31+(1-A_CSCogs)*Headcount!I32 -> 190140.9 | J13: =Headcount!J30+Headcount!J31+(1-A_CSCogs)*Headcount!J32 -> 194515.44 | ... AL13: =Headcount!AL30+Headcount!AL31+(1-A_CSCogs)*Headcount!AL32 -> 350418.03
A14: Marketing programmes | B14: $ | C14: =L_Mktg*(1+A_MktgG)^(YEAR(C$5)-2026) -> 150000 | D14: =L_Mktg*(1+A_MktgG)^(YEAR(D$5)-2026) -> 150000 | E14: =L_Mktg*(1+A_MktgG)^(YEAR(E$5)-2026) -> 150000 | F14: =L_Mktg*(1+A_MktgG)^(YEAR(F$5)-2026) -> 150000 | G14: =L_Mktg*(1+A_MktgG)^(YEAR(G$5)-2026) -> 150000 | H14: =L_Mktg*(1+A_MktgG)^(YEAR(H$5)-2026) -> 150000 | I14: =L_Mktg*(1+A_MktgG)^(YEAR(I$5)-2026) -> 150000 | J14: =L_Mktg*(1+A_MktgG)^(YEAR(J$5)-2026) -> 150000 | ... AL14: =L_Mktg*(1+A_MktgG)^(YEAR(AL$5)-2026) -> 216000
A15: Travel and entertainment | B15: $ | C15: =A_TravelPct*C13 -> 3277.8723 | D15: =A_TravelPct*D13 -> 3365.3632 | E15: =A_TravelPct*E13 -> 3452.8542 | F15: =A_TravelPct*F13 -> 3540.3451 | G15: =A_TravelPct*G13 -> 3627.8361 | H15: =A_TravelPct*H13 -> 3715.327 | I15: =A_TravelPct*I13 -> 3802.8179 | J15: =A_TravelPct*J13 -> 3890.3089 | ... AL15: =A_TravelPct*AL13 -> 7008.3606
A16: Software and tools | B16: $ | C16: =A_SoftHead*(Headcount!C18+Headcount!C19+Headcount!C20) -> 2925 | D16: =A_SoftHead*(Headcount!D18+Headcount!D19+Headcount!D20) -> 3000 | E16: =A_SoftHead*(Headcount!E18+Headcount!E19+Headcount!E20) -> 3075 | F16: =A_SoftHead*(Headcount!F18+Headcount!F19+Headcount!F20) -> 3150 | G16: =A_SoftHead*(Headcount!G18+Headcount!G19+Headcount!G20) -> 3225 | H16: =A_SoftHead*(Headcount!H18+Headcount!H19+Headcount!H20) -> 3300 | I16: =A_SoftHead*(Headcount!I18+Headcount!I19+Headcount!I20) -> 3375 | J16: =A_SoftHead*(Headcount!J18+Headcount!J19+Headcount!J20) -> 3450 | ... AL16: =A_SoftHead*(Headcount!AL18+Headcount!AL19+Headcount!AL20) -> 5850
A17: Total S&M | B17: $ | C17: =SUM(C13:C16) -> 320096.49 | D17: =SUM(D13:D16) -> 324633.52 | E17: =SUM(E13:E16) -> 329170.56 | F17: =SUM(F13:F16) -> 333707.6 | G17: =SUM(G13:G16) -> 338244.64 | H17: =SUM(H13:H16) -> 342781.68 | I17: =SUM(I13:I16) -> 347318.72 | J17: =SUM(J13:J16) -> 351855.75 | ... AL17: =SUM(AL13:AL16) -> 579276.39
A19: RESEARCH AND DEVELOPMENT
A20: Payroll (Engineering, Product) | B20: $ | C20: =Headcount!C28+Headcount!C29 -> 234104.44 | D20: =Headcount!D28+Headcount!D29 -> 240068.89 | E20: =Headcount!E28+Headcount!E29 -> 246033.33 | F20: =Headcount!F28+Headcount!F29 -> 251997.78 | G20: =Headcount!G28+Headcount!G29 -> 257962.22 | H20: =Headcount!H28+Headcount!H29 -> 263926.67 | I20: =Headcount!I28+Headcount!I29 -> 269891.11 | J20: =Headcount!J28+Headcount!J29 -> 275855.56 | ... AL20: =Headcount!AL28+Headcount!AL29 -> 447548.05
A21: Software and tools | B21: $ | C21: =A_SoftHead*(Headcount!C16+Headcount!C17) -> 2462.5 | D21: =A_SoftHead*(Headcount!D16+Headcount!D17) -> 2525 | E21: =A_SoftHead*(Headcount!E16+Headcount!E17) -> 2587.5 | F21: =A_SoftHead*(Headcount!F16+Headcount!F17) -> 2650 | G21: =A_SoftHead*(Headcount!G16+Headcount!G17) -> 2712.5 | H21: =A_SoftHead*(Headcount!H16+Headcount!H17) -> 2775 | I21: =A_SoftHead*(Headcount!I16+Headcount!I17) -> 2837.5 | J21: =A_SoftHead*(Headcount!J16+Headcount!J17) -> 2900 | ... AL21: =A_SoftHead*(Headcount!AL16+Headcount!AL17) -> 4350
A22: Travel (half rate) | B22: $ | C22: =A_TravelPct/2*C20 -> 2341.0444 | D22: =A_TravelPct/2*D20 -> 2400.6889 | E22: =A_TravelPct/2*E20 -> 2460.3333 | F22: =A_TravelPct/2*F20 -> 2519.9778 | G22: =A_TravelPct/2*G20 -> 2579.6222 | H22: =A_TravelPct/2*H20 -> 2639.2667 | I22: =A_TravelPct/2*I20 -> 2698.9111 | J22: =A_TravelPct/2*J20 -> 2758.5556 | ... AL22: =A_TravelPct/2*AL20 -> 4475.4805
A23: Total R&D | B23: $ | C23: =SUM(C20:C22) -> 238907.99 | D23: =SUM(D20:D22) -> 244994.58 | E23: =SUM(E20:E22) -> 251081.17 | F23: =SUM(F20:F22) -> 257167.76 | G23: =SUM(G20:G22) -> 263254.34 | H23: =SUM(H20:H22) -> 269340.93 | I23: =SUM(I20:I22) -> 275427.52 | J23: =SUM(J20:J22) -> 281514.11 | ... AL23: =SUM(AL20:AL22) -> 456373.53
A25: GENERAL AND ADMINISTRATIVE
A26: Payroll (G&A) | B26: $ | C26: =Headcount!C33 -> 56848.611 | D26: =Headcount!D33 -> 57780.556 | E26: =Headcount!E33 -> 58712.5 | F26: =Headcount!F33 -> 59644.444 | G26: =Headcount!G33 -> 60576.389 | H26: =Headcount!H33 -> 61508.333 | I26: =Headcount!I33 -> 62440.278 | J26: =Headcount!J33 -> 63372.222 | ... AL26: =Headcount!AL33 -> 96767.147
A27: Rent and facilities (all heads) | B27: $ | C27: =A_RentHead*Headcount!C22 -> 18450 | D27: =A_RentHead*Headcount!D22 -> 18900 | E27: =A_RentHead*Headcount!E22 -> 19350 | F27: =A_RentHead*Headcount!F22 -> 19800 | G27: =A_RentHead*Headcount!G22 -> 20250 | H27: =A_RentHead*Headcount!H22 -> 20700 | I27: =A_RentHead*Headcount!I22 -> 21150 | J27: =A_RentHead*Headcount!J22 -> 21600 | ... AL27: =A_RentHead*Headcount!AL22 -> 34200
A28: Professional fees | B28: $ | C28: =A_ProfFees*(1+A_ProfG)^(YEAR(C$5)-2026) -> 30000 | D28: =A_ProfFees*(1+A_ProfG)^(YEAR(D$5)-2026) -> 30000 | E28: =A_ProfFees*(1+A_ProfG)^(YEAR(E$5)-2026) -> 30000 | F28: =A_ProfFees*(1+A_ProfG)^(YEAR(F$5)-2026) -> 30000 | G28: =A_ProfFees*(1+A_ProfG)^(YEAR(G$5)-2026) -> 30000 | H28: =A_ProfFees*(1+A_ProfG)^(YEAR(H$5)-2026) -> 30000 | I28: =A_ProfFees*(1+A_ProfG)^(YEAR(I$5)-2026) -> 30000 | J28: =A_ProfFees*(1+A_ProfG)^(YEAR(J$5)-2026) -> 30000 | ... AL28: =A_ProfFees*(1+A_ProfG)^(YEAR(AL$5)-2026) -> 33075
A29: Software and tools | B29: $ | C29: =A_SoftHead*Headcount!C21 -> 762.5 | D29: =A_SoftHead*Headcount!D21 -> 775 | E29: =A_SoftHead*Headcount!E21 -> 787.5 | F29: =A_SoftHead*Headcount!F21 -> 800 | G29: =A_SoftHead*Headcount!G21 -> 812.5 | H29: =A_SoftHead*Headcount!H21 -> 825 | I29: =A_SoftHead*Headcount!I21 -> 837.5 | J29: =A_SoftHead*Headcount!J21 -> 850 | ... AL29: =A_SoftHead*Headcount!AL21 -> 1200
A30: Travel (half rate) | B30: $ | C30: =A_TravelPct/2*C26 -> 568.48611 | D30: =A_TravelPct/2*D26 -> 577.80556 | E30: =A_TravelPct/2*E26 -> 587.125 | F30: =A_TravelPct/2*F26 -> 596.44444 | G30: =A_TravelPct/2*G26 -> 605.76389 | H30: =A_TravelPct/2*H26 -> 615.08333 | I30: =A_TravelPct/2*I26 -> 624.40278 | J30: =A_TravelPct/2*J26 -> 633.72222 | ... AL30: =A_TravelPct/2*AL26 -> 967.67147
A31: Total G&A | B31: $ | C31: =SUM(C26:C30) -> 106629.6 | D31: =SUM(D26:D30) -> 108033.36 | E31: =SUM(E26:E30) -> 109437.12 | F31: =SUM(F26:F30) -> 110840.89 | G31: =SUM(G26:G30) -> 112244.65 | H31: =SUM(H26:H30) -> 113648.42 | I31: =SUM(I26:I30) -> 115052.18 | J31: =SUM(J26:J30) -> 116455.94 | ... AL31: =SUM(AL26:AL30) -> 166209.82
A33: Total operating expenses (S&M + R&D + G&A) | B33: $ | C33: =C17+C23+C31 -> 665634.07 | D33: =D17+D23+D31 -> 677661.46 | E33: =E17+E23+E31 -> 689688.85 | F33: =F17+F23+F31 -> 701716.25 | G33: =G17+G23+G31 -> 713743.64 | H33: =H17+H23+H31 -> 725771.03 | I33: =I17+I23+I31 -> 737798.42 | J33: =J17+J23+J31 -> 749825.81 | ... AL33: =AL17+AL23+AL31 -> 1201859.7
A35: CAPEX PLACEHOLDER AND DEPRECIATION | V2 replaces with a full schedule
A36: Capex | B36: $ | C36: =A_Capex -> 40000 | D36: =A_Capex -> 40000 | E36: =A_Capex -> 40000 | F36: =A_Capex -> 40000 | G36: =A_Capex -> 40000 | H36: =A_Capex -> 40000 | I36: =A_Capex -> 40000 | J36: =A_Capex -> 40000 | ... AL36: =A_Capex -> 40000
A37: Depreciation and amortisation | B37: $ | C37: =SUM($C$36:C36)/A_Life -> 1111.1111 | D37: =SUM($C$36:D36)/A_Life -> 2222.2222 | E37: =SUM($C$36:E36)/A_Life -> 3333.3333 | F37: =SUM($C$36:F36)/A_Life -> 4444.4444 | G37: =SUM($C$36:G36)/A_Life -> 5555.5556 | H37: =SUM($C$36:H36)/A_Life -> 6666.6667 | I37: =SUM($C$36:I36)/A_Life -> 7777.7778 | J37: =SUM($C$36:J36)/A_Life -> 8888.8889 | ... AL37: =SUM($C$36:AL36)/A_Life -> 40000
A39: Depreciation is straight line over the asset life on cumulative capex to date; within the 36-month horizon no cohort fully depreciates.

Sheet Income Statement
A1: NOVAFLOW ANALYTICS | E1: back to cover
A2: Income Statement | E2: monthly P&L with NOL-adjusted tax and FY rollups
A5: Month | C5: =ModelStart -> 46023 | D5: =EDATE(C5,1) -> 46054 | E5: =EDATE(D5,1) -> 46082 | F5: =EDATE(E5,1) -> 46113 | G5: =EDATE(F5,1) -> 46143 | H5: =EDATE(G5,1) -> 46174 | I5: =EDATE(H5,1) -> 46204 | J5: =EDATE(I5,1) -> 46235 | K5: =EDATE(J5,1) -> 46266 | ... AL5: =EDATE(AK5,1) -> 47088 | AN5: FY2026 | AO5: FY2027 | AP5: FY2028
A7: Revenue | B7: $ | C7: ='Revenue Model'!C36 -> 358076 | D7: ='Revenue Model'!D36 -> 383221.74 | E7: ='Revenue Model'!E36 -> 408438.46 | F7: ='Revenue Model'!F36 -> 433727.37 | G7: ='Revenue Model'!G36 -> 459089.7 | H7: ='Revenue Model'!H36 -> 484526.68 | I7: ='Revenue Model'!I36 -> 510039.53 | J7: ='Revenue Model'!J36 -> 535629.49 | ... AL7: ='Revenue Model'!AL36 -> 1288470.8 | AN7: =SUM(C7:N7) -> 5972751.6 | AO7: =SUM(O7:Z7) -> 9717992.8 | AP7: =SUM(AA7:AL7) -> 13621032
A8: Cost of goods sold | B8: $ | C8: ='Operating Expenses'!C10 -> 69735.74 | D8: ='Operating Expenses'!D10 -> 72871.157 | E8: ='Operating Expenses'!E10 -> 76012.961 | F8: ='Operating Expenses'!F10 -> 79161.263 | G8: ='Operating Expenses'!G10 -> 82316.173 | H8: ='Operating Expenses'!H10 -> 85477.801 | I8: ='Operating Expenses'!I10 -> 88646.258 | J8: ='Operating Expenses'!J10 -> 91821.654 | ... AL8: ='Operating Expenses'!AL10 -> 200875.55 | AN8: =SUM(C8:N8) -> 1045226.2 | AO8: =SUM(O8:Z8) -> 1568621.2 | AP8: =SUM(AA8:AL8) -> 2151446.4
A9: Gross profit | B9: $ | C9: =C7-C8 -> 288340.26 | D9: =D7-D8 -> 310350.59 | E9: =E7-E8 -> 332425.5 | F9: =F7-F8 -> 354566.11 | G9: =G7-G8 -> 376773.53 | H9: =H7-H8 -> 399048.88 | I9: =I7-I8 -> 421393.27 | J9: =J7-J8 -> 443807.83 | ... AL9: =AL7-AL8 -> 1087595.3 | AN9: =SUM(C9:N9) -> 4927525.3 | AO9: =SUM(O9:Z9) -> 8149371.6 | AP9: =SUM(AA9:AL9) -> 11469585
A10: Gross margin | B10: % | C10: =IFERROR(C9/C7,0) -> 0.80524877 | D10: =IFERROR(D9/D7,0) -> 0.80984598 | E10: =IFERROR(E9/E7,0) -> 0.81389372 | F10: =IFERROR(F9/F7,0) -> 0.81748612 | G10: =IFERROR(G9/G7,0) -> 0.82069697 | H10: =IFERROR(H9/H7,0) -> 0.82358494 | I10: =IFERROR(I9/I7,0) -> 0.82619728 | J10: =IFERROR(J9/J7,0) -> 0.82857244 | ... AL10: =IFERROR(AL9/AL7,0) -> 0.84409772 | AN10: =IFERROR(AN9/AN7,0) -> 0.82500088 | AO10: =IFERROR(AO9/AO7,0) -> 0.83858588 | AP10: =IFERROR(AP9/AP7,0) -> 0.84204967
A12: Sales and marketing | B12: $ | C12: ='Operating Expenses'!C17 -> 320096.49 | D12: ='Operating Expenses'!D17 -> 324633.52 | E12: ='Operating Expenses'!E17 -> 329170.56 | F12: ='Operating Expenses'!F17 -> 333707.6 | G12: ='Operating Expenses'!G17 -> 338244.64 | H12: ='Operating Expenses'!H17 -> 342781.68 | I12: ='Operating Expenses'!I17 -> 347318.72 | J12: ='Operating Expenses'!J17 -> 351855.75 | ... AL12: ='Operating Expenses'!AL17 -> 579276.39 | AN12: =SUM(C12:N12) -> 4140602.4 | AO12: =SUM(O12:Z12) -> 5296693 | AP12: =SUM(AA12:AL12) -> 6605844.7
A13: Research and development | B13: $ | C13: ='Operating Expenses'!C23 -> 238907.99 | D13: ='Operating Expenses'!D23 -> 244994.58 | E13: ='Operating Expenses'!E23 -> 251081.17 | F13: ='Operating Expenses'!F23 -> 257167.76 | G13: ='Operating Expenses'!G23 -> 263254.34 | H13: ='Operating Expenses'!H23 -> 269340.93 | I13: ='Operating Expenses'!I23 -> 275427.52 | J13: ='Operating Expenses'!J23 -> 281514.11 | ... AL13: ='Operating Expenses'!AL23 -> 456373.53 | AN13: =SUM(C13:N13) -> 3268610.7 | AO13: =SUM(O13:Z13) -> 4208938.8 | AP13: =SUM(AA13:AL13) -> 5130499.7
A14: General and administrative | B14: $ | C14: ='Operating Expenses'!C31 -> 106629.6 | D14: ='Operating Expenses'!D31 -> 108033.36 | E14: ='Operating Expenses'!E31 -> 109437.12 | F14: ='Operating Expenses'!F31 -> 110840.89 | G14: ='Operating Expenses'!G31 -> 112244.65 | H14: ='Operating Expenses'!H31 -> 113648.42 | I14: ='Operating Expenses'!I31 -> 115052.18 | J14: ='Operating Expenses'!J31 -> 116455.94 | ... AL14: ='Operating Expenses'!AL31 -> 166209.82 | AN14: =SUM(C14:N14) -> 1372203.6 | AO14: =SUM(O14:Z14) -> 1627812.4 | AP14: =SUM(AA14:AL14) -> 1896800.1
A15: Total operating expenses | B15: $ | C15: =C12+C13+C14 -> 665634.07 | D15: =D12+D13+D14 -> 677661.46 | E15: =E12+E13+E14 -> 689688.85 | F15: =F12+F13+F14 -> 701716.25 | G15: =G12+G13+G14 -> 713743.64 | H15: =H12+H13+H14 -> 725771.03 | I15: =I12+I13+I14 -> 737798.42 | J15: =J12+J13+J14 -> 749825.81 | ... AL15: =AL12+AL13+AL14 -> 1201859.7 | AN15: =SUM(C15:N15) -> 8781416.7 | AO15: =SUM(O15:Z15) -> 11133444 | AP15: =SUM(AA15:AL15) -> 13633145
A17: EBITDA | B17: $ | C17: =C9-C15 -> -377293.81 | D17: =D9-D15 -> -367310.88 | E17: =E9-E15 -> -357263.36 | F17: =F9-F15 -> -347150.14 | G17: =G9-G15 -> -336970.11 | H17: =H9-H15 -> -326722.15 | I17: =I9-I15 -> -316405.14 | J17: =J9-J15 -> -306017.97 | ... AL17: =AL9-AL15 -> -114264.45 | AN17: =SUM(C17:N17) -> -3853891.3 | AO17: =SUM(O17:Z17) -> -2984072.7 | AP17: =SUM(AA17:AL17) -> -2163559.4
A18: EBITDA margin | B18: % | C18: =IFERROR(C17/C7,0) -> -1.0536696 | D18: =IFERROR(D17/D7,0) -> -0.9584813 | E18: =IFERROR(E17/E7,0) -> -0.87470547 | F18: =IFERROR(F17/F7,0) -> -0.8003879 | G18: =IFERROR(G17/G7,0) -> -0.73399623 | H18: =IFERROR(H17/H7,0) -> -0.67431199 | I18: =IFERROR(I17/I7,0) -> -0.62035416 | J18: =IFERROR(J17/J7,0) -> -0.57132399 | ... AL18: =IFERROR(AL17/AL7,0) -> -0.088682214 | AN18: =IFERROR(AN17/AN7,0) -> -0.64524555 | AO18: =IFERROR(AO17/AO7,0) -> -0.30706677 | AP18: =IFERROR(AP17/AP7,0) -> -0.15883961
A19: Depreciation and amortisation | B19: $ | C19: ='Operating Expenses'!C37 -> 1111.1111 | D19: ='Operating Expenses'!D37 -> 2222.2222 | E19: ='Operating Expenses'!E37 -> 3333.3333 | F19: ='Operating Expenses'!F37 -> 4444.4444 | G19: ='Operating Expenses'!G37 -> 5555.5556 | H19: ='Operating Expenses'!H37 -> 6666.6667 | I19: ='Operating Expenses'!I37 -> 7777.7778 | J19: ='Operating Expenses'!J37 -> 8888.8889 | ... AL19: ='Operating Expenses'!AL37 -> 40000 | AN19: =SUM(C19:N19) -> 86666.667 | AO19: =SUM(O19:Z19) -> 246666.67 | AP19: =SUM(AA19:AL19) -> 406666.67
A20: EBIT | B20: $ | C20: =C17-C19 -> -378404.92 | D20: =D17-D19 -> -369533.1 | E20: =E17-E19 -> -360596.69 | F20: =F17-F19 -> -351594.58 | G20: =G17-G19 -> -342525.66 | H20: =H17-H19 -> -333388.82 | I20: =I17-I19 -> -324182.92 | J20: =J17-J19 -> -314906.86 | ... AL20: =AL17-AL19 -> -154264.45 | AN20: =SUM(C20:N20) -> -3940558 | AO20: =SUM(O20:Z20) -> -3230739.3 | AP20: =SUM(AA20:AL20) -> -2570226.1
A22: Pre-tax income (no debt in V1) | B22: $ | C22: =C20 -> -378404.92 | D22: =D20 -> -369533.1 | E22: =E20 -> -360596.69 | F22: =F20 -> -351594.58 | G22: =G20 -> -342525.66 | H22: =H20 -> -333388.82 | I22: =I20 -> -324182.92 | J22: =J20 -> -314906.86 | ... AL22: =AL20 -> -154264.45 | AN22: =SUM(C22:N22) -> -3940558 | AO22: =SUM(O22:Z22) -> -3230739.3 | AP22: =SUM(AA22:AL22) -> -2570226.1
A23: memo: cumulative pre-tax income | B23: $ | C23: =C22 -> -378404.92 | D23: =C23+D22 -> -747938.02 | E23: =D23+E22 -> -1108534.7 | F23: =E23+F22 -> -1460129.3 | G23: =F23+G22 -> -1802655 | H23: =G23+H22 -> -2136043.8 | I23: =H23+I22 -> -2460226.7 | J23: =I23+J22 -> -2775133.6 | K23: =J23+K22 -> -3080693.1 | ... AL23: =AK23+AL22 -> -9741523.4
A24: memo: cumulative tax at statutory rate | B24: $ | C24: =A_TaxRate*MAX(0,C23) -> 0 | D24: =A_TaxRate*MAX(0,D23) -> 0 | E24: =A_TaxRate*MAX(0,E23) -> 0 | F24: =A_TaxRate*MAX(0,F23) -> 0 | G24: =A_TaxRate*MAX(0,G23) -> 0 | H24: =A_TaxRate*MAX(0,H23) -> 0 | I24: =A_TaxRate*MAX(0,I23) -> 0 | J24: =A_TaxRate*MAX(0,J23) -> 0 | ... AL24: =A_TaxRate*MAX(0,AL23) -> 0
A25: Tax charge (NOL carryforward applied) | B25: $ | C25: =C24 -> 0 | D25: =MAX(0,D24-C24) -> 0 | E25: =MAX(0,E24-D24) -> 0 | F25: =MAX(0,F24-E24) -> 0 | G25: =MAX(0,G24-F24) -> 0 | H25: =MAX(0,H24-G24) -> 0 | I25: =MAX(0,I24-H24) -> 0 | J25: =MAX(0,J24-I24) -> 0 | K25: =MAX(0,K24-J24) -> 0 | ... AL25: =MAX(0,AL24-AK24) -> 0 | AN25: =SUM(C25:N25) -> 0 | AO25: =SUM(O25:Z25) -> 0 | AP25: =SUM(AA25:AL25) -> 0
A26: Net income | B26: $ | C26: =C22-C25 -> -378404.92 | D26: =D22-D25 -> -369533.1 | E26: =E22-E25 -> -360596.69 | F26: =F22-F25 -> -351594.58 | G26: =G22-G25 -> -342525.66 | H26: =H22-H25 -> -333388.82 | I26: =I22-I25 -> -324182.92 | J26: =J22-J25 -> -314906.86 | ... AL26: =AL22-AL25 -> -154264.45 | AN26: =SUM(C26:N26) -> -3940558 | AO26: =SUM(O26:Z26) -> -3230739.3 | AP26: =SUM(AA26:AL26) -> -2570226.1
A27: Net margin | B27: % | C27: =IFERROR(C26/C7,0) -> -1.0567726 | D27: =IFERROR(D26/D7,0) -> -0.96428009 | E27: =IFERROR(E26/E7,0) -> -0.88286664 | F27: =IFERROR(F26/F7,0) -> -0.81063499 | G27: =IFERROR(G26/G7,0) -> -0.74609747 | H27: =IFERROR(H26/H7,0) -> -0.68807112 | I27: =IFERROR(I26/I7,0) -> -0.63560352 | J27: =IFERROR(J26/J7,0) -> -0.58791921 | ... AL27: =IFERROR(AL26/AL7,0) -> -0.11972677 | AN27: =IFERROR(AN26/AN7,0) -> -0.65975589 | AO27: =IFERROR(AO26/AO7,0) -> -0.33244924 | AP27: =IFERROR(AP26/AP7,0) -> -0.1886954
A29: Tax: no charge until cumulative pre-tax income turns positive; early losses shelter later profits (simple NOL carryforward, no deferred tax asset in V1).

Sheet Cash Flow
A1: NOVAFLOW ANALYTICS | E1: back to cover
A2: Cash Flow | E2: indirect method; structured for V2 working capital and financing
A5: Month | C5: =ModelStart -> 46023 | D5: =EDATE(C5,1) -> 46054 | E5: =EDATE(D5,1) -> 46082 | F5: =EDATE(E5,1) -> 46113 | G5: =EDATE(F5,1) -> 46143 | H5: =EDATE(G5,1) -> 46174 | I5: =EDATE(H5,1) -> 46204 | J5: =EDATE(I5,1) -> 46235 | K5: =EDATE(J5,1) -> 46266 | ... AL5: =EDATE(AK5,1) -> 47088 | AN5: FY2026 | AO5: FY2027 | AP5: FY2028
A7: OPERATING CASH FLOW
A8: Net income | B8: $ | C8: ='Income Statement'!C26 -> -378404.92 | D8: ='Income Statement'!D26 -> -369533.1 | E8: ='Income Statement'!E26 -> -360596.69 | F8: ='Income Statement'!F26 -> -351594.58 | G8: ='Income Statement'!G26 -> -342525.66 | H8: ='Income Statement'!H26 -> -333388.82 | I8: ='Income Statement'!I26 -> -324182.92 | J8: ='Income Statement'!J26 -> -314906.86 | ... AL8: ='Income Statement'!AL26 -> -154264.45 | AN8: =SUM(C8:N8) -> -3940558 | AO8: =SUM(O8:Z8) -> -3230739.3 | AP8: =SUM(AA8:AL8) -> -2570226.1
A9: Add back: depreciation and amortisation | B9: $ | C9: ='Income Statement'!C19 -> 1111.1111 | D9: ='Income Statement'!D19 -> 2222.2222 | E9: ='Income Statement'!E19 -> 3333.3333 | F9: ='Income Statement'!F19 -> 4444.4444 | G9: ='Income Statement'!G19 -> 5555.5556 | H9: ='Income Statement'!H19 -> 6666.6667 | I9: ='Income Statement'!I19 -> 7777.7778 | J9: ='Income Statement'!J19 -> 8888.8889 | ... AL9: ='Income Statement'!AL19 -> 40000 | AN9: =SUM(C9:N9) -> 86666.667 | AO9: =SUM(O9:Z9) -> 246666.67 | AP9: =SUM(AA9:AL9) -> 406666.67
A10: Movement in deferred revenue | B10: $ | C10: ='Revenue Model'!C52 -> 148500 | D10: ='Revenue Model'!D52 -> 148986.15 | E10: ='Revenue Model'!E52 -> 149473.89 | F10: ='Revenue Model'!F52 -> 149963.23 | G10: ='Revenue Model'!G52 -> 150454.17 | H10: ='Revenue Model'!H52 -> 150946.72 | I10: ='Revenue Model'!I52 -> 151440.88 | J10: ='Revenue Model'!J52 -> 151936.66 | ... AL10: ='Revenue Model'!AL52 -> 166497.24 | AN10: =SUM(C10:N10) -> 1814438.7 | AO10: =SUM(O10:Z10) -> 1887016.2 | AP10: =SUM(AA10:AL10) -> 1962496.8
A11: Working capital movements (V2 bolt-on)
A12: Operating cash flow | B12: $ | C12: =C8+C9+C10 -> -228793.81 | D12: =D8+D9+D10 -> -218324.72 | E12: =E8+E9+E10 -> -207789.46 | F12: =F8+F9+F10 -> -197186.91 | G12: =G8+G9+G10 -> -186515.94 | H12: =H8+H9+H10 -> -175775.43 | I12: =I8+I9+I10 -> -164964.26 | J12: =J8+J9+J10 -> -154081.32 | ... AL12: =AL8+AL9+AL10 -> 52232.789 | AN12: =SUM(C12:N12) -> -2039452.7 | AO12: =SUM(O12:Z12) -> -1097056.5 | AP12: =SUM(AA12:AL12) -> -201062.55
A14: INVESTING AND FINANCING
